Workbook

Sheet Estimates-on-the-use-of-water-(
A1: name | B1: income_group | C1: income_group_num | D1: pop_n (th) | E1: pop_u % | F1: wat_bas_n | G1: wat_lim_n | H1: wat_unimp_n | I1: wat_sur_n | J1: wat_bas_r | K1: wat_lim_r | L1: wat_unimp_r | M1: wat_sur_r | N1: wat_bas_u | O1: wat_lim_u | P1: wat_unimp_u | Q1: wat_sur_u | R1: value_cnt | S1: pop_n_billion | T1: pop_u_value | U1: pop_r_value | V1: pop_u (th) | W1: pop_r (th) | X1: pop_r % | Y1: Rounded_up_pop_U % | Z1: Rounded_up_pop_R % | AA1: Rounded-up pop_n (m) | AB1: Rounded-up pop_u (m) | AC1: Rounded-up pop_r(m) | AD1: wat_bas_n(rounded) | AE1: Rounded-up pop_u (m) 2 | AF1: Column 1 | AG1: Column 2 | AH1: Column 3 | AI1: Column 4
A2: Tokelau | B2: NAN | C2: =IF(B2="NAN",0, IF(B2="Low income",1, IF(B2="Lower middle income",2, IF(B2="Upper middle income",3, IF(B2="High income",4,""))))) -> 0 | D2: 1.35 | E2: 0 | F2: 99.707677 | G2: 0 | H2: 0.29232335 | I2: 0 | J2: 99.707677 | K2: 0 | L2: 0.29232335 | M2: 0 | N2: NAN | O2: NAN | P2: NAN | Q2: NAN | R2: =COUNTA(A2:Q2) -> 17 | S2: =D2*1000 -> 1350 | T2: =S2*E2/100 -> 0 | U2: =S2*X2/100 -> 1350 | V2: =T2/1000 -> 0 | W2: =U2/1000 -> 1.35 | X2: =100-E2 -> 100 | Y2: =ROUNDUP(E2,0) -> 0 | Z2: =ROUNDUP(X2,0) -> 100 | AA2: =ROUNDUP(D2/1000,0) -> 1 | AB2: =ROUNDUP(V2/1000,0) -> 0 | AC2: =ROUNDUP(W2/1000,0) -> 1 | AD2: =ROUND(F2,0) -> 100 | AE2: =ROUNDUP(E2/1000,0) -> 0
A3: Niue | B3: NAN | C3: =IF(B3="NAN",0, IF(B3="Low income",1, IF(B3="Lower middle income",2, IF(B3="Upper middle income",3, IF(B3="High income",4,""))))) -> 0 | D3: 1.618 | E3: 46.202003 | F3: 97.010876 | G3: 0 | H3: 2.9891238 | I3: 0 | J3: NAN | K3: NAN | L3: NAN | M3: NAN | N3: NAN | O3: NAN | P3: NAN | Q3: NAN | R3: =COUNTA(A3:Q3) -> 17 | S3: =D3*1000 -> 1618 | T3: =S3*E3/100 -> 747.54843 | U3: =S3*X3/100 -> 870.4516 | V3: =T3/1000 -> 0.74754843 | W3: =U3/1000 -> 0.8704516 | X3: =100-E3 -> 53.797997 | Y3: =ROUNDUP(E3,0) -> 47 | Z3: =ROUNDUP(X3,0) -> 54 | AA3: =ROUNDUP(D3/1000,0) -> 1 | AB3: =ROUNDUP(V3/1000,0) -> 1 | AC3: =ROUNDUP(W3/1000,0) -> 1 | AD3: =ROUND(F3,0) -> 97 | AE3: =ROUNDUP(E3/1000,0) -> 1
A4: Falkland Islands (Malvinas) | B4: NAN | C4: =IF(B4="NAN",0, IF(B4="Low income",1, IF(B4="Lower middle income",2, IF(B4="Upper middle income",3, IF(B4="High income",4,""))))) -> 0 | D4: 3.483 | E4: 78.507996 | F4: 95.308927 | G4: 0 | H4: 4.6910726 | I4: 0 | J4: 78.172943 | K4: 0 | L4: 21.827057 | M4: 0 | N4: 100 | O4: 0 | P4: 0 | Q4: 0 | R4: =COUNTA(A4:Q4) -> 17 | S4: =D4*1000 -> 3483 | T4: =S4*E4/100 -> 2734.4335 | U4: =S4*X4/100 -> 748.56652 | V4: =T4/1000 -> 2.7344335 | W4: =U4/1000 -> 0.74856652 | X4: =100-E4 -> 21.492004 | Y4: =ROUNDUP(E4,0) -> 79 | Z4: =ROUNDUP(X4,0) -> 22 | AA4: =ROUNDUP(D4/1000,0) -> 1 | AB4: =ROUNDUP(V4/1000,0) -> 1 | AC4: =ROUNDUP(W4/1000,0) -> 1 | AD4: =ROUND(F4,0) -> 95 | AE4: =ROUNDUP(E4/1000,0) -> 1
A5: Montserrat | B5: NAN | C5: =IF(B5="NAN",0, IF(B5="Low income",1, IF(B5="Lower middle income",2, IF(B5="Upper middle income",3, IF(B5="High income",4,""))))) -> 0 | D5: 4.9990001 | E5: 9.1149998 | F5: 98.077483 | G5: 0 | H5: 1.9225174 | I5: 0 | J5: NAN | K5: NAN | L5: NAN | M5: NAN | N5: NAN | O5: NAN | P5: NAN | Q5: NAN | R5: =COUNTA(A5:Q5) -> 17 | S5: =D5*1000 -> 4999.0001 | T5: =S5*E5/100 -> 455.65885 | U5: =S5*X5/100 -> 4543.3412 | V5: =T5/1000 -> 0.45565885 | W5: =U5/1000 -> 4.5433412 | X5: =100-E5 -> 90.885 | Y5: =ROUNDUP(E5,0) -> 10 | Z5: =ROUNDUP(X5,0) -> 91 | AA5: =ROUNDUP(D5/1000,0) -> 1 | AB5: =ROUNDUP(V5/1000,0) -> 1 | AC5: =ROUNDUP(W5/1000,0) -> 1 | AD5: =ROUND(F5,0) -> 98 | AE5: =ROUNDUP(E5/1000,0) -> 1
A6: Saint Pierre and Miquelon | B6: NAN | C6: =IF(B6="NAN",0, IF(B6="Low income",1, IF(B6="Lower middle income",2, IF(B6="Upper middle income",3, IF(B6="High income",4,""))))) -> 0 | D6: 5.7950001 | E6: 89.961998 | F6: 91.4 | G6: 0 | H6: 8.6 | I6: 0 | J6: NAN | K6: NAN | L6: NAN | M6: NAN | N6: NAN | O6: NAN | P6: NAN | Q6: NAN | R6: =COUNTA(A6:Q6) -> 17 | S6: =D6*1000 -> 5795.0001 | T6: =S6*E6/100 -> 5213.2979 | U6: =S6*X6/100 -> 581.70222 | V6: =T6/1000 -> 5.2132979 | W6: =U6/1000 -> 0.58170222 | X6: =100-E6 -> 10.038002 | Y6: =ROUNDUP(E6,0) -> 90 | Z6: =ROUNDUP(X6,0) -> 11 | AA6: =ROUNDUP(D6/1000,0) -> 1 | AB6: =ROUNDUP(V6/1000,0) -> 1 | AC6: =ROUNDUP(W6/1000,0) -> 1 | AD6: =ROUND(F6,0) -> 91 | AE6: =ROUNDUP(E6/1000,0) -> 1
A7: Saint Helena | B7: NAN | C7: =IF(B7="NAN",0, IF(B7="Low income",1, IF(B7="Lower middle income",2, IF(B7="Upper middle income",3, IF(B7="High income",4,""))))) -> 0 | D7: 6.0710001 | E7: 40.082001 | F7: 99.1 | G7: 0 | H7: 0.9 | I7: 0 | J7: NAN | K7: NAN | L7: NAN | M7: NAN | N7: NAN | O7: NAN | P7: NAN | Q7: NAN | R7: =COUNTA(A7:Q7) -> 17 | S7: =D7*1000 -> 6071.0001 | T7: =S7*E7/100 -> 2433.3783 | U7: =S7*X7/100 -> 3637.6218 | V7: =T7/1000 -> 2.4333783 | W7: =U7/1000 -> 3.6376218 | X7: =100-E7 -> 59.917999 | Y7: =ROUNDUP(E7,0) -> 41 | Z7: =ROUNDUP(X7,0) -> 60 | AA7: =ROUNDUP(D7/1000,0) -> 1 | AB7: =ROUNDUP(V7/1000,0) -> 1 | AC7: =ROUNDUP(W7/1000,0) -> 1 | AD7: =ROUND(F7,0) -> 99 | AE7: =ROUNDUP(E7/1000,0) -> 1
A8: Saint Barthelemy | B8: NAN | C8: =IF(B8="NAN",0, IF(B8="Low income",1, IF(B8="Lower middle income",2, IF(B8="Upper middle income",3, IF(B8="High income",4,""))))) -> 0 | D8: 9.885 | E8: 100 | F8: 100 | G8: 0 | H8: 0 | I8: 0 | J8: NAN | K8: NAN | L8: NAN | M8: NAN | N8: 100 | O8: 0 | P8: 0 | Q8: 0 | R8: =COUNTA(A8:Q8) -> 17 | S8: =D8*1000 -> 9885 | T8: =S8*E8/100 -> 9885 | U8: =S8*X8/100 -> 0 | V8: =T8/1000 -> 9.885 | W8: =U8/1000 -> 0 | X8: =100-E8 -> 0 | Y8: =ROUNDUP(E8,0) -> 100 | Z8: =ROUNDUP(X8,0) -> 0 | AA8: =ROUNDUP(D8/1000,0) -> 1 | AB8: =ROUNDUP(V8/1000,0) -> 1 | AC8: =ROUNDUP(W8/1000,0) -> 0 | AD8: =ROUND(F8,0) -> 100 | AE8: =ROUNDUP(E8/1000,0) -> 1
A9: Nauru | B9: High income | C9: =IF(B9="NAN",0, IF(B9="Low income",1, IF(B9="Lower middle income",2, IF(B9="Upper middle income",3, IF(B9="High income",4,""))))) -> 4 | D9: 10.834 | E9: 100 | F9: 100 | G9: 0 | H9: 0 | I9: 0 | J9: NAN | K9: NAN | L9: NAN | M9: NAN | N9: 100 | O9: 0 | P9: 0 | Q9: 0 | R9: =COUNTA(A9:Q9) -> 17 | S9: =D9*1000 -> 10834 | T9: =S9*E9/100 -> 10834 | U9: =S9*X9/100 -> 0 | V9: =T9/1000 -> 10.834 | W9: =U9/1000 -> 0 | X9: =100-E9 -> 0 | Y9: =ROUNDUP(E9,0) -> 100 | Z9: =ROUNDUP(X9,0) -> 0 | AA9: =ROUNDUP(D9/1000,0) -> 1 | AB9: =ROUNDUP(V9/1000,0) -> 1 | AC9: =ROUNDUP(W9/1000,0) -> 0 | AD9: =ROUND(F9,0) -> 100 | AE9: =ROUNDUP(E9/1000,0) -> 1
A10: Wallis and Futuna Islands | B10: NAN | C10: =IF(B10="NAN",0, IF(B10="Low income",1, IF(B10="Lower middle income",2, IF(B10="Upper middle income",3, IF(B10="High income",4,""))))) -> 0 | D10: 11.246 | E10: 0 | F10: 99.143287 | G10: 0 | H10: 0.85671264 | I10: 0 | J10: 99.143287 | K10: 0 | L10: 0.85671264 | M10: 0 | N10: NAN | O10: NAN | P10: NAN | Q10: NAN | R10: =COUNTA(A10:Q10) -> 17 | S10: =D10*1000 -> 11246 | T10: =S10*E10/100 -> 0 | U10: =S10*X10/100 -> 11246 | V10: =T10/1000 -> 0 | W10: =U10/1000 -> 11.246 | X10: =100-E10 -> 100 | Y10: =ROUNDUP(E10,0) -> 0 | Z10: =ROUNDUP(X10,0) -> 100 | AA10: =ROUNDUP(D10/1000,0) -> 1 | AB10: =ROUNDUP(V10/1000,0) -> 0 | AC10: =ROUNDUP(W10/1000,0) -> 1 | AD10: =ROUND(F10,0) -> 99 | AE10: =ROUNDUP(E10/1000,0) -> 0
A11: Tuvalu | B11: Upper middle income | C11: =IF(B11="NAN",0, IF(B11="Low income",1, IF(B11="Lower middle income",2, IF(B11="Upper middle income",3, IF(B11="High income",4,""))))) -> 3 | D11: 11.792 | E11: 64.014 | F11: 100 | G11: 0 | H11: 0 | I11: 0 | J11: 100 | K11: 0 | L11: 0 | M11: 0 | N11: 100 | O11: 0 | P11: 0 | Q11: 0 | R11: =COUNTA(A11:Q11) -> 17 | S11: =D11*1000 -> 11792 | T11: =S11*E11/100 -> 7548.5308 | U11: =S11*X11/100 -> 4243.4691 | V11: =T11/1000 -> 7.5485308 | W11: =U11/1000 -> 4.2434691 | X11: =100-E11 -> 35.986 | Y11: =ROUNDUP(E11,0) -> 65 | Z11: =ROUNDUP(X11,0) -> 36 | AA11: =ROUNDUP(D11/1000,0) -> 1 | AB11: =ROUNDUP(V11/1000,0) -> 1 | AC11: =ROUNDUP(W11/1000,0) -> 1 | AD11: =ROUND(F11,0) -> 100 | AE11: =ROUNDUP(E11/1000,0) -> 1
A12: Cook Islands | B12: NAN | C12: =IF(B12="NAN",0, IF(B12="Low income",1, IF(B12="Lower middle income",2, IF(B12="Upper middle income",3, IF(B12="High income",4,""))))) -> 0 | D12: 17.563999 | E12: 75.495003 | F12: 99.97161 | G12: 0 | H12: 0.028389783 | I12: 0 | J12: NAN | K12: NAN | L12: NAN | M12: NAN | N12: NAN | O12: NAN | P12: NAN | Q12: NAN | R12: =COUNTA(A12:Q12) -> 17 | S12: =D12*1000 -> 17563.999 | T12: =S12*E12/100 -> 13259.942 | U12: =S12*X12/100 -> 4304.0575 | V12: =T12/1000 -> 13.259942 | W12: =U12/1000 -> 4.3040575 | X12: =100-E12 -> 24.504997 | Y12: =ROUNDUP(E12,0) -> 76 | Z12: =ROUNDUP(X12,0) -> 25 | AA12: =ROUNDUP(D12/1000,0) -> 1 | AB12: =ROUNDUP(V12/1000,0) -> 1 | AC12: =ROUNDUP(W12/1000,0) -> 1 | AD12: =ROUND(F12,0) -> 100 | AE12: =ROUNDUP(E12/1000,0) -> 1
A13: Palau | B13: Upper middle income | C13: =IF(B13="NAN",0, IF(B13="Low income",1, IF(B13="Lower middle income",2, IF(B13="Upper middle income",3, IF(B13="High income",4,""))))) -> 3 | D13: 18.091999 | E13: 80.987999 | F13: 99.657545 | G13: 0 | H13: 0.3424545 | I13: 0 | J13: 99.756985 | K13: 0 | L13: 0.24301497 | M13: 0 | N13: 99.634202 | O13: 0 | P13: 0.36579801 | Q13: 0 | R13: =COUNTA(A13:Q13) -> 17 | S13: =D13*1000 -> 18091.999 | T13: =S13*E13/100 -> 14652.348 | U13: =S13*X13/100 -> 3439.651 | V13: =T13/1000 -> 14.652348 | W13: =U13/1000 -> 3.439651 | X13: =100-E13 -> 19.012001 | Y13: =ROUNDUP(E13,0) -> 81 | Z13: =ROUNDUP(X13,0) -> 20 | AA13: =ROUNDUP(D13/1000,0) -> 1 | AB13: =ROUNDUP(V13/1000,0) -> 1 | AC13: =ROUNDUP(W13/1000,0) -> 1 | AD13: =ROUND(F13,0) -> 100 | AE13: =ROUNDUP(E13/1000,0) -> 1
A14: British Virgin Islands | B14: High income | C14: =IF(B14="NAN",0, IF(B14="Low income",1, IF(B14="Lower middle income",2, IF(B14="Upper middle income",3, IF(B14="High income",4,""))))) -> 4 | D14: 30.237 | E14: 48.514999 | F14: 99.864384 | G14: 0 | H14: 0.13561644 | I14: 0 | J14: NAN | K14: NAN | L14: NAN | M14: NAN | N14: NAN | O14: NAN | P14: NAN | Q14: NAN | R14: =COUNTA(A14:Q14) -> 17 | S14: =D14*1000 -> 30237 | T14: =S14*E14/100 -> 14669.48 | U14: =S14*X14/100 -> 15567.519 | V14: =T14/1000 -> 14.66948 | W14: =U14/1000 -> 15.567519 | X14: =100-E14 -> 51.485001 | Y14: =ROUNDUP(E14,0) -> 49 | Z14: =ROUNDUP(X14,0) -> 52 | AA14: =ROUNDUP(D14/1000,0) -> 1 | AB14: =ROUNDUP(V14/1000,0) -> 1 | AC14: =ROUNDUP(W14/1000,0) -> 1 | AD14: =ROUND(F14,0) -> 100 | AE14: =ROUNDUP(E14/1000,0) -> 1
A15: Gibraltar | B15: High income | C15: =IF(B15="NAN",0, IF(B15="Low income",1, IF(B15="Lower middle income",2, IF(B15="Upper middle income",3, IF(B15="High income",4,""))))) -> 4 | D15: 33.691002 | E15: 100 | F15: 100 | G15: 0 | H15: 0 | I15: 0 | J15: NAN | K15: NAN | L15: NAN | M15: NAN | N15: 100 | O15: 0 | P15: 0 | Q15: 0 | R15: =COUNTA(A15:Q15) -> 17 | S15: =D15*1000 -> 33691.002 | T15: =S15*E15/100 -> 33691.002 | U15: =S15*X15/100 -> 0 | V15: =T15/1000 -> 33.691002 | W15: =U15/1000 -> 0 | X15: =100-E15 -> 0 | Y15: =ROUNDUP(E15,0) -> 100 | Z15: =ROUNDUP(X15,0) -> 0 | AA15: =ROUNDUP(D15/1000,0) -> 1 | AB15: =ROUNDUP(V15/1000,0) -> 1 | AC15: =ROUNDUP(W15/1000,0) -> 0 | AD15: =ROUND(F15,0) -> 100 | AE15: =ROUNDUP(E15/1000,0) -> 1
A16: San Marino | B16: High income | C16: =IF(B16="NAN",0, IF(B16="Low income",1, IF(B16="Lower middle income",2, IF(B16="Upper middle income",3, IF(B16="High income",4,""))))) -> 4 | D16: 33.938 | E16: 97.499001 | F16: 100 | G16: 0 | H16: 0 | I16: 0 | J16: NAN | K16: NAN | L16: NAN | M16: NAN | N16: NAN | O16: NAN | P16: NAN | Q16: NAN | R16: =COUNTA(A16:Q16) -> 17 | S16: =D16*1000 -> 33938 | T16: =S16*E16/100 -> 33089.211 | U16: =S16*X16/100 -> 848.78919 | V16: =T16/1000 -> 33.089211 | W16: =U16/1000 -> 0.84878919 | X16: =100-E16 -> 2.5009995 | Y16: =ROUNDUP(E16,0) -> 98 | Z16: =ROUNDUP(X16,0) -> 3 | AA16: =ROUNDUP(D16/1000,0) -> 1 | AB16: =ROUNDUP(V16/1000,0) -> 1 | AC16: =ROUNDUP(W16/1000,0) -> 1 | AD16: =ROUND(F16,0) -> 100 | AE16: =ROUNDUP(E16/1000,0) -> 1
A17: Liechtenstein | B17: High income | C17: =IF(B17="NAN",0, IF(B17="Low income",1, IF(B17="Lower middle income",2, IF(B17="Upper middle income",3, IF(B17="High income",4,""))))) -> 4 | D17: 38.137001 | E17: 14.416 | F17: 100 | G17: 0 | H17: 0 | I17: 0 | J17: NAN | K17: NAN | L17: NAN | M17: NAN | N17: NAN | O17: NAN | P17: NAN | Q17: NAN | R17: =COUNTA(A17:Q17) -> 17 | S17: =D17*1000 -> 38137.001 | T17: =S17*E17/100 -> 5497.8302 | U17: =S17*X17/100 -> 32639.171 | V17: =T17/1000 -> 5.4978302 | W17: =U17/1000 -> 32.639171 | X17: =100-E17 -> 85.584 | Y17: =ROUNDUP(E17,0) -> 15 | Z17: =ROUNDUP(X17,0) -> 86 | AA17: =ROUNDUP(D17/1000,0) -> 1 | AB17: =ROUNDUP(V17/1000,0) -> 1 | AC17: =ROUNDUP(W17/1000,0) -> 1 | AD17: =ROUND(F17,0) -> 100 | AE17: =ROUNDUP(E17/1000,0) -> 1
A18: Saint Martin (French part) | B18: High income | C18: =IF(B18="NAN",0, IF(B18="Low income",1, IF(B18="Lower middle income",2, IF(B18="Upper middle income",3, IF(B18="High income",4,""))))) -> 4 | D18: 38.659 | E18: 100 | F18: 99.999271 | G18: 0 | H18: 0.00072861055 | I18: 0 | J18: NAN | K18: NAN | L18: NAN | M18: NAN | N18: 99.999271 | O18: 0 | P18: 0.00072861055 | Q18: 0 | R18: =COUNTA(A18:Q18) -> 17 | S18: =D18*1000 -> 38659 | T18: =S18*E18/100 -> 38659 | U18: =S18*X18/100 -> 0 | V18: =T18/1000 -> 38.659 | W18: =U18/1000 -> 0 | X18: =100-E18 -> 0 | Y18: =ROUNDUP(E18,0) -> 100 | Z18: =ROUNDUP(X18,0) -> 0 | AA18: =ROUNDUP(D18/1000,0) -> 1 | AB18: =ROUNDUP(V18/1000,0) -> 1 | AC18: =ROUNDUP(W18/1000,0) -> 0 | AD18: =ROUND(F18,0) -> 100 | AE18: =ROUNDUP(E18/1000,0) -> 1
A19: Monaco | B19: High income | C19: =IF(B19="NAN",0, IF(B19="Low income",1, IF(B19="Lower middle income",2, IF(B19="Upper middle income",3, IF(B19="High income",4,""))))) -> 4 | D19: 39.243999 | E19: 100 | F19: 100 | G19: 0 | H19: 0 | I19: 0 | J19: NAN | K19: NAN | L19: NAN | M19: NAN | N19: 100 | O19: 0 | P19: 0 | Q19: 0 | R19: =COUNTA(A19:Q19) -> 17 | S19: =D19*1000 -> 39243.999 | T19: =S19*E19/100 -> 39243.999 | U19: =S19*X19/100 -> 0 | V19: =T19/1000 -> 39.243999 | W19: =U19/1000 -> 0 | X19: =100-E19 -> 0 | Y19: =ROUNDUP(E19,0) -> 100 | Z19: =ROUNDUP(X19,0) -> 0 | AA19: =ROUNDUP(D19/1000,0) -> 1 | AB19: =ROUNDUP(V19/1000,0) -> 1 | AC19: =ROUNDUP(W19/1000,0) -> 0 | AD19: =ROUND(F19,0) -> 100 | AE19: =ROUNDUP(E19/1000,0) -> 1
A20: Faeroe Islands | B20: High income | C20: =IF(B20="NAN",0, IF(B20="Low income",1, IF(B20="Lower middle income",2, IF(B20="Upper middle income",3, IF(B20="High income",4,""))))) -> 4 | D20: 48.865002 | E20: 42.397999 | F20: 100 | G20: 0 | H20: 0 | I20: 0 | J20: NAN | K20: NAN | L20: NAN | M20: NAN | N20: NAN | O20: NAN | P20: NAN | Q20: NAN | R20: =COUNTA(A20:Q20) -> 17 | S20: =D20*1000 -> 48865.002 | T20: =S20*E20/100 -> 20717.783 | U20: =S20*X20/100 -> 28147.219 | V20: =T20/1000 -> 20.717783 | W20: =U20/1000 -> 28.147219 | X20: =100-E20 -> 57.602001 | Y20: =ROUNDUP(E20,0) -> 43 | Z20: =ROUNDUP(X20,0) -> 58 | AA20: =ROUNDUP(D20/1000,0) -> 1 | AB20: =ROUNDUP(V20/1000,0) -> 1 | AC20: =ROUNDUP(W20/1000,0) -> 1 | AD20: =ROUND(F20,0) -> 100 | AE20: =ROUNDUP(E20/1000,0) -> 1
A21: American Samoa | B21: Upper middle income | C21: =IF(B21="NAN",0, IF(B21="Low income",1, IF(B21="Lower middle income",2, IF(B21="Upper middle income",3, IF(B21="High income",4,""))))) -> 3 | D21: 55.196999 | E21: 87.153 | F21: 99.773772 | G21: 0 | H21: 0.22622834 | I21: 0 | J21: NAN | K21: NAN | L21: NAN | M21: NAN | N21: NAN | O21: NAN | P21: NAN | Q21: NAN | R21: =COUNTA(A21:Q21) -> 17 | S21: =D21*1000 -> 55196.999 | T21: =S21*E21/100 -> 48105.84 | U21: =S21*X21/100 -> 7091.1585 | V21: =T21/1000 -> 48.10584 | W21: =U21/1000 -> 7.0911585 | X21: =100-E21 -> 12.847 | Y21: =ROUNDUP(E21,0) -> 88 | Z21: =ROUNDUP(X21,0) -> 13 | AA21: =ROUNDUP(D21/1000,0) -> 1 | AB21: =ROUNDUP(V21/1000,0) -> 1 | AC21: =ROUNDUP(W21/1000,0) -> 1 | AD21: =ROUND(F21,0) -> 100 | AE21: =ROUNDUP(E21/1000,0) -> 1
A22: Greenland | B22: High income | C22: =IF(B22="NAN",0, IF(B22="Low income",1, IF(B22="Lower middle income",2, IF(B22="Upper middle income",3, IF(B22="High income",4,""))))) -> 4 | D22: 56.771999 | E22: 87.282005 | F22: 100 | G22: 0 | H22: 0 | I22: 0 | J22: 100 | K22: 0 | L22: 0 | M22: 0 | N22: 100 | O22: 0 | P22: 0 | Q22: 0 | R22: =COUNTA(A22:Q22) -> 17 | S22: =D22*1000 -> 56771.999 | T22: =S22*E22/100 -> 49551.74 | U22: =S22*X22/100 -> 7220.2599 | V22: =T22/1000 -> 49.551739 | W22: =U22/1000 -> 7.2202599 | X22: =100-E22 -> 12.717995 | Y22: =ROUNDUP(E22,0) -> 88 | Z22: =ROUNDUP(X22,0) -> 13 | AA22: =ROUNDUP(D22/1000,0) -> 1 | AB22: =ROUNDUP(V22/1000,0) -> 1 | AC22: =ROUNDUP(W22/1000,0) -> 1 | AD22: =ROUND(F22,0) -> 100 | AE22: =ROUNDUP(E22/1000,0) -> 1
A23: Northern Mariana Islands | B23: High income | C23: =IF(B23="NAN",0, IF(B23="Low income",1, IF(B23="Lower middle income",2, IF(B23="Upper middle income",3, IF(B23="High income",4,""))))) -> 4 | D23: 57.556999 | E23: 91.797997 | F23: 100 | G23: 0 | H23: 0 | I23: 0 | J23: NAN | K23: NAN | L23: NAN | M23: NAN | N23: NAN | O23: NAN | P23: NAN | Q23: NAN | R23: =COUNTA(A23:Q23) -> 17 | S23: =D23*1000 -> 57556.999 | T23: =S23*E23/100 -> 52836.172 | U23: =S23*X23/100 -> 4720.8271 | V23: =T23/1000 -> 52.836172 | W23: =U23/1000 -> 4.7208271 | X23: =100-E23 -> 8.2020035 | Y23: =ROUNDUP(E23,0) -> 92 | Z23: =ROUNDUP(X23,0) -> 9 | AA23: =ROUNDUP(D23/1000,0) -> 1 | AB23: =ROUNDUP(V23/1000,0) -> 1 | AC23: =ROUNDUP(W23/1000,0) -> 1 | AD23: =ROUND(F23,0) -> 100 | AE23: =ROUNDUP(E23/1000,0) -> 1
A24: Marshall Islands | B24: Upper middle income | C24: =IF(B24="NAN",0, IF(B24="Low income",1, IF(B24="Lower middle income",2, IF(B24="Upper middle income",3, IF(B24="High income",4,""))))) -> 3 | D24: 59.194 | E24: 77.793991 | F24: 88.572047 | G24: 11.387979 | H24: 0.039974026 | I24: 0 | J24: 94.42972 | K24: 5.39028 | L24: 0.18 | M24: 0 | N24: 86.9 | O24: 13.1 | P24: 0 | Q24: 0 | R24: =COUNTA(A24:Q24) -> 17 | S24: =E24*1000 -> 77793.991 | T24: =S24*F24/100 -> 68903.73 | U24: =S24*X24/100 -> 17274.941 | V24: =T24/1000 -> 68.90373 | W24: =U24/1000 -> 17.274941 | X24: =100-E24 -> 22.206009 | Y24: =ROUNDUP(E24,0) -> 78 | Z24: =ROUNDUP(X24,0) -> 23 | AA24: =ROUNDUP(D24/1000,0) -> 1 | AB24: =ROUNDUP(V24/1000,0) -> 1 | AC24: =ROUNDUP(W24/1000,0) -> 1 | AD24: =ROUND(F24,0) -> 89 | AE24: =ROUNDUP(E24/1000,0) -> 1
A25: Bermuda | B25: High income | C25: =IF(B25="NAN",0, IF(B25="Low income",1, IF(B25="Lower middle income",2, IF(B25="Upper middle income",3, IF(B25="High income",4,""))))) -> 4 | D25: 62.272999 | E25: 100 | F25: 99.90314 | G25: 0 | H25: 0.096859983 | I25: 0 | J25: NAN | K25: NAN | L25: NAN | M25: NAN | N25: 99.90314 | O25: 0 | P25: 0.096859983 | Q25: 0 | R25: =COUNTA(A25:Q25) -> 17 | S25: =D25*1000 -> 62272.999 | T25: =S25*E25/100 -> 62272.999 | U25: =S25*X25/100 -> 0 | V25: =T25/1000 -> 62.272999 | W25: =U25/1000 -> 0 | X25: =100-E25 -> 0 | Y25: =ROUNDUP(E25,0) -> 100 | Z25: =ROUNDUP(X25,0) -> 0 | AA25: =ROUNDUP(D25/1000,0) -> 1 | AB25: =ROUNDUP(V25/1000,0) -> 1 | AC25: =ROUNDUP(W25/1000,0) -> 0 | AD25: =ROUND(F25,0) -> 100 | AE25: =ROUNDUP(E25/1000,0) -> 1
A26: Andorra | B26: High income | C26: =IF(B26="NAN",0, IF(B26="Low income",1, IF(B26="Lower middle income",2, IF(B26="Upper middle income",3, IF(B26="High income",4,""))))) -> 4 | D26: 77.264999 | E26: 87.916 | F26: 100 | G26: 0 | H26: 0 | I26: 0 | J26: 100 | K26: 0 | L26: 0 | M26: 0 | N26: 100 | O26: 0 | P26: 0 | Q26: 0 | R26: =COUNTA(A26:Q26) -> 17 | S26: =D26*1000 -> 77264.999 | T26: =S26*E26/100 -> 67928.297 | U26: =S26*X26/100 -> 9336.7022 | V26: =T26/1000 -> 67.928297 | W26: =U26/1000 -> 9.3367022 | X26: =100-E26 -> 12.084 | Y26: =ROUNDUP(E26,0) -> 88 | Z26: =ROUNDUP(X26,0) -> 13 | AA26: =ROUNDUP(D26/1000,0) -> 1 | AB26: =ROUNDUP(V26/1000,0) -> 1 | AC26: =ROUNDUP(W26/1000,0) -> 1 | AD26: =ROUND(F26,0) -> 100 | AE26: =ROUNDUP(E26/1000,0) -> 1
A27: Isle of Man | B27: High income | C27: =IF(B27="NAN",0, IF(B27="Low income",1, IF(B27="Lower middle income",2, IF(B27="Upper middle income",3, IF(B27="High income",4,""))))) -> 4 | D27: 85.031998 | E27: 52.898003 | F27: 99.075 | G27: 0 | H27: 0.925 | I27: 0 | J27: NAN | K27: NAN | L27: NAN | M27: NAN | N27: NAN | O27: NAN | P27: NAN | Q27: NAN | R27: =COUNTA(A27:Q27) -> 17 | S27: =D27*1000 -> 85031.998 | T27: =S27*E27/100 -> 44980.228 | U27: =S27*X27/100 -> 40051.769 | V27: =T27/1000 -> 44.980228 | W27: =U27/1000 -> 40.051769 | X27: =100-E27 -> 47.101997 | Y27: =ROUNDUP(E27,0) -> 53 | Z27: =ROUNDUP(X27,0) -> 48 | AA27: =ROUNDUP(D27/1000,0) -> 1 | AB27: =ROUNDUP(V27/1000,0) -> 1 | AC27: =ROUNDUP(W27/1000,0) -> 1 | AD27: =ROUND(F27,0) -> 99 | AE27: =ROUNDUP(E27/1000,0) -> 1
A28: United States Virgin Islands | B28: High income | C28: =IF(B28="NAN",0, IF(B28="Low income",1, IF(B28="Lower middle income",2, IF(B28="Upper middle income",3, IF(B28="High income",4,""))))) -> 4 | D28: 104.423 | E28: 95.939003 | F28: 98.718267 | G28: 0 | H28: 1.2817326 | I28: 0 | J28: NAN | K28: NAN | L28: NAN | M28: NAN | N28: NAN | O28: NAN | P28: NAN | Q28: NAN | R28: =COUNTA(A28:Q28) -> 17 | S28: =D28*1000 -> 104423 | T28: =S28*E28/100 -> 100182.38 | U28: =S28*X28/100 -> 4240.6148 | V28: =T28/1000 -> 100.18238 | W28: =U28/1000 -> 4.2406148 | X28: =100-E28 -> 4.060997 | Y28: =ROUNDUP(E28,0) -> 96 | Z28: =ROUNDUP(X28,0) -> 5 | AA28: =ROUNDUP(D28/1000,0) -> 1 | AB28: =ROUNDUP(V28/1000,0) -> 1 | AC28: =ROUNDUP(W28/1000,0) -> 1 | AD28: =ROUND(F28,0) -> 99 | AE28: =ROUNDUP(E28/1000,0) -> 1
A29: Tonga | B29: Upper middle income | C29: =IF(B29="NAN",0, IF(B29="Low income",1, IF(B29="Lower middle income",2, IF(B29="Upper middle income",3, IF(B29="High income",4,""))))) -> 3 | D29: 105.697 | E29: 23.098999 | F29: 98.731081 | G29: 0.8814973 | H29: 0.38742188 | I29: 0 | J29: 98.468079 | K29: 1.1031597 | L29: 0.42876176 | M29: 0 | N29: 99.606658 | O29: 0.14354054 | P29: 0.24980128 | Q29: 0 | R29: =COUNTA(A29:Q29) -> 17 | S29: =D29*1000 -> 105697 | T29: =S29*E29/100 -> 24414.949 | U29: =S29*X29/100 -> 81282.05 | V29: =T29/1000 -> 24.414949 | W29: =U29/1000 -> 81.28205 | X29: =100-E29 -> 76.901001 | Y29: =ROUNDUP(E29,0) -> 24 | Z29: =ROUNDUP(X29,0) -> 77 | AA29: =ROUNDUP(D29/1000,0) -> 1 | AB29: =ROUNDUP(V29/1000,0) -> 1 | AC29: =ROUNDUP(W29/1000,0) -> 1 | AD29: =ROUND(F29,0) -> 99 | AE29: =ROUNDUP(E29/1000,0) -> 1
A30: Kiribati | B30: Lower middle income | C30: =IF(B30="NAN",0, IF(B30="Low income",1, IF(B30="Lower middle income",2, IF(B30="Upper middle income",3, IF(B30="High income",4,""))))) -> 2 | D30: 119.446 | E30: 55.593998 | F30: 77.970921 | G30: 4.0768996 | H30: 17.95218 | I30: 0 | J30: 60.994185 | K30: 2.0966098 | L30: 36.909205 | M30: 0 | N30: 91.531175 | O30: 5.6586665 | P30: 2.8101587 | Q30: 0 | R30: =COUNTA(A30:Q30) -> 17 | S30: =D30*1000 -> 119446 | T30: =S30*E30/100 -> 66404.806 | U30: =S30*X30/100 -> 53041.193 | V30: =T30/1000 -> 66.404806 | W30: =U30/1000 -> 53.041193 | X30: =100-E30 -> 44.406002 | Y30: =ROUNDUP(E30,0) -> 56 | Z30: =ROUNDUP(X30,0) -> 45 | AA30: =ROUNDUP(D30/1000,0) -> 1 | AB30: =ROUNDUP(V30/1000,0) -> 1 | AC30: =ROUNDUP(W30/1000,0) -> 1 | AD30: =ROUND(F30,0) -> 78 | AE30: =ROUNDUP(E30/1000,0) -> 1
A31: Guam | B31: High income | C31: =IF(B31="NAN",0, IF(B31="Low income",1, IF(B31="Lower middle income",2, IF(B31="Upper middle income",3, IF(B31="High income",4,""))))) -> 4 | D31: 168.783 | E31: 94.938004 | F31: 99.6952 | G31: 0 | H31: 0.3048 | I31: 0 | J31: NAN | K31: NAN | L31: NAN | M31: NAN | N31: NAN | O31: NAN | P31: NAN | Q31: NAN | R31: =COUNTA(A31:Q31) -> 17 | S31: =D31*1000 -> 168783 | T31: =S31*E31/100 -> 160239.22 | U31: =S31*X31/100 -> 8543.7897 | V31: =T31/1000 -> 160.23922 | W31: =U31/1000 -> 8.5437897 | X31: =100-E31 -> 5.0619965 | Y31: =ROUNDUP(E31,0) -> 95 | Z31: =ROUNDUP(X31,0) -> 6 | AA31: =ROUNDUP(D31/1000,0) -> 1 | AB31: =ROUNDUP(V31/1000,0) -> 1 | AC31: =ROUNDUP(W31/1000,0) -> 1 | AD31: =ROUND(F31,0) -> 100 | AE31: =ROUNDUP(E31/1000,0) -> 1
A32: Saint Lucia | B32: Upper middle income | C32: =IF(B32="NAN",0, IF(B32="Low income",1, IF(B32="Lower middle income",2, IF(B32="Upper middle income",3, IF(B32="High income",4,""))))) -> 3 | D32: 183.629 | E32: 18.841 | F32: 96.887845 | G32: 1.8156522 | H32: 1.2965033 | I32: 0 | J32: 96.814024 | K32: 1.7341523 | L32: 1.4518239 | M32: 0 | N32: 97.205822 | O32: 2.1667189 | P32: 0.62745892 | Q32: 0 | R32: =COUNTA(A32:Q32) -> 17 | S32: =D32*1000 -> 183629 | T32: =S32*E32/100 -> 34597.539 | U32: =S32*X32/100 -> 149031.46 | V32: =T32/1000 -> 34.597539 | W32: =U32/1000 -> 149.03146 | X32: =100-E32 -> 81.159 | Y32: =ROUNDUP(E32,0) -> 19 | Z32: =ROUNDUP(X32,0) -> 82 | AA32: =ROUNDUP(D32/1000,0) -> 1 | AB32: =ROUNDUP(V32/1000,0) -> 1 | AC32: =ROUNDUP(W32/1000,0) -> 1 | AD32: =ROUND(F32,0) -> 97 | AE32: =ROUNDUP(E32/1000,0) -> 1
A33: Samoa | B33: Lower middle income | C33: =IF(B33="NAN",0, IF(B33="Low income",1, IF(B33="Lower middle income",2, IF(B33="Upper middle income",3, IF(B33="High income",4,""))))) -> 2 | D33: 198.41 | E33: 17.889 | F33: 91.837725 | G33: 6.5209 | H33: 1.4186234 | I33: 0.22275207 | J33: 91.780323 | K33: 6.2207033 | L33: 1.7276922 | M33: 0.27128163 | N33: 92.10119 | O33: 7.89881 | P33: 0 | Q33: 0 | R33: =COUNTA(A33:Q33) -> 17 | S33: =D33*1000 -> 198410 | T33: =S33*E33/100 -> 35493.565 | U33: =S33*X33/100 -> 162916.44 | V33: =T33/1000 -> 35.493565 | W33: =U33/1000 -> 162.91644 | X33: =100-E33 -> 82.111 | Y33: =ROUNDUP(E33,0) -> 18 | Z33: =ROUNDUP(X33,0) -> 83 | AA33: =ROUNDUP(D33/1000,0) -> 1 | AB33: =ROUNDUP(V33/1000,0) -> 1 | AC33: =ROUNDUP(W33/1000,0) -> 1 | AD33: =ROUND(F33,0) -> 92 | AE33: =ROUNDUP(E33/1000,0) -> 1
A34: Sao Tome and Principe | B34: Lower middle income | C34: =IF(B34="NAN",0, IF(B34="Low income",1, IF(B34="Lower middle income",2, IF(B34="Upper middle income",3, IF(B34="High income",4,""))))) -> 2 | D34: 219.161 | E34: 74.354004 | F34: 78.226455 | G34: 20.237983 | H34: 0.44351993 | I34: 1.0920419 | J34: 74.300614 | K34: 19.711843 | L34: 1.7294057 | M34: 4.2581372 | N34: 79.580543 | O34: 20.419457 | P34: 0 | Q34: 0 | R34: =COUNTA(A34:Q34) -> 17 | S34: =D34*1000 -> 219161 | T34: =S34*E34/100 -> 162954.98 | U34: =S34*X34/100 -> 56206.02 | V34: =T34/1000 -> 162.95498 | W34: =U34/1000 -> 56.20602 | X34: =100-E34 -> 25.645996 | Y34: =ROUNDUP(E34,0) -> 75 | Z34: =ROUNDUP(X34,0) -> 26 | AA34: =ROUNDUP(D34/1000,0) -> 1 | AB34: =ROUNDUP(V34/1000,0) -> 1 | AC34: =ROUNDUP(W34/1000,0) -> 1 | AD34: =ROUND(F34,0) -> 78 | AE34: =ROUNDUP(E34/1000,0) -> 1
A35: Mayotte | B35: NAN | C35: =IF(B35="NAN",0, IF(B35="Low income",1, IF(B35="Lower middle income",2, IF(B35="Upper middle income",3, IF(B35="High income",4,""))))) -> 0 | D35: 272.81299 | E35: 45.750999 | F35: 96.37118 | G35: 0 | H35: 3.6288203 | I35: NAN | J35: NAN | K35: NAN | L35: NAN | M35: NAN | N35: NAN | O35: NAN | P35: NAN | Q35: NAN | R35: =COUNTA(A35:Q35) -> 17 | S35: =D35*1000 -> 272812.99 | T35: =S35*E35/100 -> 124814.67 | U35: =S35*X35/100 -> 147998.32 | V35: =T35/1000 -> 124.81467 | W35: =U35/1000 -> 147.99832 | X35: =100-E35 -> 54.249001 | Y35: =ROUNDUP(E35,0) -> 46 | Z35: =ROUNDUP(X35,0) -> 55 | AA35: =ROUNDUP(D35/1000,0) -> 1 | AB35: =ROUNDUP(V35/1000,0) -> 1 | AC35: =ROUNDUP(W35/1000,0) -> 1 | AD35: =ROUND(F35,0) -> 96 | AE35: =ROUNDUP(E35/1000,0) -> 1
A36: French Polynesia | B36: High income | C36: =IF(B36="NAN",0, IF(B36="Low income",1, IF(B36="Lower middle income",2, IF(B36="Upper middle income",3, IF(B36="High income",4,""))))) -> 4 | D36: 280.90399 | E36: 61.975002 | F36: 100 | G36: 0 | H36: 0 | I36: 0 | J36: NAN | K36: NAN | L36: NAN | M36: NAN | N36: NAN | O36: NAN | P36: NAN | Q36: NAN | R36: =COUNTA(A36:Q36) -> 17 | S36: =D36*1000 -> 280903.99 | T36: =S36*E36/100 -> 174090.26 | U36: =S36*X36/100 -> 106813.74 | V36: =T36/1000 -> 174.09026 | W36: =U36/1000 -> 106.81374 | X36: =100-E36 -> 38.024998 | Y36: =ROUNDUP(E36,0) -> 62 | Z36: =ROUNDUP(X36,0) -> 39 | AA36: =ROUNDUP(D36/1000,0) -> 1 | AB36: =ROUNDUP(V36/1000,0) -> 1 | AC36: =ROUNDUP(W36/1000,0) -> 1 | AD36: =ROUND(F36,0) -> 100 | AE36: =ROUNDUP(E36/1000,0) -> 1
A37: New Caledonia | B37: High income | C37: =IF(B37="NAN",0, IF(B37="Low income",1, IF(B37="Lower middle income",2, IF(B37="Upper middle income",3, IF(B37="High income",4,""))))) -> 4 | D37: 285.491 | E37: 71.517998 | F37: 99.305321 | G37: 0 | H37: 0.69467943 | I37: 0 | J37: NAN | K37: NAN | L37: NAN | M37: NAN | N37: NAN | O37: NAN | P37: NAN | Q37: NAN | R37: =COUNTA(A37:Q37) -> 17 | S37: =D37*1000 -> 285491 | T37: =S37*E37/100 -> 204177.45 | U37: =S37*X37/100 -> 81313.552 | V37: =T37/1000 -> 204.17745 | W37: =U37/1000 -> 81.313552 | X37: =100-E37 -> 28.482002 | Y37: =ROUNDUP(E37,0) -> 72 | Z37: =ROUNDUP(X37,0) -> 29 | AA37: =ROUNDUP(D37/1000,0) -> 1 | AB37: =ROUNDUP(V37/1000,0) -> 1 | AC37: =ROUNDUP(W37/1000,0) -> 1 | AD37: =ROUND(F37,0) -> 99 | AE37: =ROUNDUP(E37/1000,0) -> 1
A38: Barbados | B38: High income | C38: =IF(B38="NAN",0, IF(B38="Low income",1, IF(B38="Lower middle income",2, IF(B38="Upper middle income",3, IF(B38="High income",4,""))))) -> 4 | D38: 287.371 | E38: 31.191 | F38: 98.51445 | G38: 0.26760058 | H38: 1.217949 | I38: 0 | J38: NAN | K38: NAN | L38: NAN | M38: NAN | N38: NAN | O38: NAN | P38: NAN | Q38: NAN | R38: =COUNTA(A38:Q38) -> 17 | S38: =D38*1000 -> 287371 | T38: =S38*E38/100 -> 89633.889 | U38: =S38*X38/100 -> 197737.11 | V38: =T38/1000 -> 89.633889 | W38: =U38/1000 -> 197.73711 | X38: =100-E38 -> 68.809 | Y38: =ROUNDUP(E38,0) -> 32 | Z38: =ROUNDUP(X38,0) -> 69 | AA38: =ROUNDUP(D38/1000,0) -> 1 | AB38: =ROUNDUP(V38/1000,0) -> 1 | AC38: =ROUNDUP(W38/1000,0) -> 1 | AD38: =ROUND(F38,0) -> 99 | AE38: =ROUNDUP(E38/1000,0) -> 1
A39: French Guiana | B39: NAN | C39: =IF(B39="NAN",0, IF(B39="Low income",1, IF(B39="Lower middle income",2, IF(B39="Upper middle income",3, IF(B39="High income",4,""))))) -> 0 | D39: 298.68201 | E39: 85.82 | F39: 93.782216 | G39: 0 | H39: 6.2177837 | I39: 0 | J39: NAN | K39: NAN | L39: NAN | M39: NAN | N39: NAN | O39: NAN | P39: NAN | Q39: NAN | R39: =COUNTA(A39:Q39) -> 17 | S39: =D39*1000 -> 298682.01 | T39: =S39*E39/100 -> 256328.9 | U39: =S39*X39/100 -> 42353.109 | V39: =T39/1000 -> 256.3289 | W39: =U39/1000 -> 42.353109 | X39: =100-E39 -> 14.18 | Y39: =ROUNDUP(E39,0) -> 86 | Z39: =ROUNDUP(X39,0) -> 15 | AA39: =ROUNDUP(D39/1000,0) -> 1 | AB39: =ROUNDUP(V39/1000,0) -> 1 | AC39: =ROUNDUP(W39/1000,0) -> 1 | AD39: =ROUND(F39,0) -> 94 | AE39: =ROUNDUP(E39/1000,0) -> 1
A40: Vanuatu | B40: Lower middle income | C40: =IF(B40="NAN",0, IF(B40="Low income",1, IF(B40="Lower middle income",2, IF(B40="Upper middle income",3, IF(B40="High income",4,""))))) -> 2 | D40: 307.14999 | E40: 25.525002 | F40: 91.231191 | G40: 1.0623851 | H40: 0 | I40: 7.7064242 | J40: 88.397201 | K40: 1.2551327 | L40: 0 | M40: 10.347666 | N40: 99.5 | O40: 0.5 | P40: 0 | Q40: 0 | R40: =COUNTA(A40:Q40) -> 17 | S40: =D40*1000 -> 307149.99 | T40: =S40*E40/100 -> 78400.041 | U40: =S40*X40/100 -> 228749.95 | V40: =T40/1000 -> 78.400041 | W40: =U40/1000 -> 228.74995 | X40: =100-E40 -> 74.474998 | Y40: =ROUNDUP(E40,0) -> 26 | Z40: =ROUNDUP(X40,0) -> 75 | AA40: =ROUNDUP(D40/1000,0) -> 1 | AB40: =ROUNDUP(V40/1000,0) -> 1 | AC40: =ROUNDUP(W40/1000,0) -> 1 | AD40: =ROUND(F40,0) -> 91 | AE40: =ROUNDUP(E40/1000,0) -> 1
...

Sheet Pivot Table 1
A12: income_group_num | B12: AVERAGE of wat_bas_n | C12: AVERAGE of wat_lim_n | D12: AVERAGE of wat_unimp_n | E12: AVERAGE of wat_sur_n
A13: =A3 -> 1 | B13: =D3 -> 62.819374 | C13: =E3 -> 16.548388 | D13: =F3 -> 15.210931 | E13: =G3 -> 5.4213074
A14: =A4 -> 2 | B14: =D4 -> 82.210493 | C14: =E4 -> 5.6884251 | D14: =F4 -> 7.8981438 | E14: =G4 -> 4.2853488
A15: =A5 -> 3 | B15: =D5 -> 96.430472 | C15: =E5 -> 1.5611896 | D15: =F5 -> 1.4834061 | E15: =G5 -> 0.57265356
A16: =A6 -> 4 | B16: =D6 -> 99.560198 | C16: =E6 -> 0.17690109 | D16: =F6 -> 0.24084589 | E16: =G6 -> 0.022055377
A17: =A7 | B17: =D7 -> #DIV/0! | C17: =E7 -> #DIV/0! | D17: =F7 -> #DIV/0! | E17: =G7 -> #DIV/0!
A18: =A8 -> Grand Total | B18: =D8 -> 89.864783 | C18: =E8 -> 3.8652653 | D18: =F8 -> 4.4180107 | E18: =G8 -> 1.9154886
A20: =A9
A45: income_group_num | B45: AVERAGE of pop_u %
A46: =A3 -> 1 | B46: =C3 -> 36.044653
A47: =A4 -> 2 | B47: =C4 -> 48.789904
A48: =A5 -> 3 | B48: =C5 -> 64.685696
A49: =A6 -> 4 | B49: =C6 -> 79.355457
A72: income_group_num | B72: SUM of pop_n (th)
A73: =A3 -> 1 | B73: =B3 -> 5.9042516e+08
A74: =A4 -> 2 | B74: =B4 -> 3399310231
A75: =A5 -> 3 | B75: =B5 -> 2547637907
A76: =A6 -> 4 | B76: =B6 -> 1212076068
A78: =A7

Sheet ORDERED POP%_M
A1: Rounded_up_pop_U % | B1: Rounded_up_pop_R % | C1: Rounded-up pop_n (m)
A2: ='Estimates-on-the-use-of-water-('!Y2 -> 0 | B2: ='Estimates-on-the-use-of-water-('!Z8 -> 0 | C2: ='Estimates-on-the-use-of-water-('!AA2 -> 1
A3: ='Estimates-on-the-use-of-water-('!Y10 -> 0 | B3: ='Estimates-on-the-use-of-water-('!Z9 -> 0 | C3: ='Estimates-on-the-use-of-water-('!AA3 -> 1
A4: ='Estimates-on-the-use-of-water-('!Y5 -> 10 | B4: ='Estimates-on-the-use-of-water-('!Z15 -> 0 | C4: ='Estimates-on-the-use-of-water-('!AA4 -> 1
A5: ='Estimates-on-the-use-of-water-('!Y118 -> 14 | B5: ='Estimates-on-the-use-of-water-('!Z18 -> 0 | C5: ='Estimates-on-the-use-of-water-('!AA5 -> 1
A6: ='Estimates-on-the-use-of-water-('!Y138 -> 14 | B6: ='Estimates-on-the-use-of-water-('!Z19 -> 0 | C6: ='Estimates-on-the-use-of-water-('!AA6 -> 1
A7: ='Estimates-on-the-use-of-water-('!Y17 -> 15 | B7: ='Estimates-on-the-use-of-water-('!Z25 -> 0 | C7: ='Estimates-on-the-use-of-water-('!AA7 -> 1
A8: ='Estimates-on-the-use-of-water-('!Y159 -> 17 | B8: ='Estimates-on-the-use-of-water-('!Z52 -> 0 | C8: ='Estimates-on-the-use-of-water-('!AA8 -> 1
A9: ='Estimates-on-the-use-of-water-('!Y33 -> 18 | B9: ='Estimates-on-the-use-of-water-('!Z87 -> 0 | C9: ='Estimates-on-the-use-of-water-('!AA9 -> 1
A10: ='Estimates-on-the-use-of-water-('!Y140 -> 18 | B10: ='Estimates-on-the-use-of-water-('!Z102 -> 0 | C10: ='Estimates-on-the-use-of-water-('!AA10 -> 1
A11: ='Estimates-on-the-use-of-water-('!Y154 -> 18 | B11: ='Estimates-on-the-use-of-water-('!Z112 -> 0 | C11: ='Estimates-on-the-use-of-water-('!AA11 -> 1
A12: ='Estimates-on-the-use-of-water-('!Y32 -> 19 | B12: ='Estimates-on-the-use-of-water-('!Z56 -> 1 | C12: ='Estimates-on-the-use-of-water-('!AA12 -> 1
A13: ='Estimates-on-the-use-of-water-('!Y158 -> 19 | B13: ='Estimates-on-the-use-of-water-('!Z78 -> 1 | C13: ='Estimates-on-the-use-of-water-('!AA13 -> 1
A14: ='Estimates-on-the-use-of-water-('!Y132 -> 21 | B14: ='Estimates-on-the-use-of-water-('!Z44 -> 2 | C14: ='Estimates-on-the-use-of-water-('!AA14 -> 1
A15: ='Estimates-on-the-use-of-water-('!Y166 -> 21 | B15: ='Estimates-on-the-use-of-water-('!Z135 -> 2 | C15: ='Estimates-on-the-use-of-water-('!AA15 -> 1
A16: ='Estimates-on-the-use-of-water-('!Y203 -> 22 | B16: ='Estimates-on-the-use-of-water-('!Z16 -> 3 | C16: ='Estimates-on-the-use-of-water-('!AA16 -> 1
A17: ='Estimates-on-the-use-of-water-('!Y29 -> 24 | B17: ='Estimates-on-the-use-of-water-('!Z28 -> 5 | C17: ='Estimates-on-the-use-of-water-('!AA17 -> 1
A18: ='Estimates-on-the-use-of-water-('!Y144 -> 24 | B18: ='Estimates-on-the-use-of-water-('!Z83 -> 5 | C18: ='Estimates-on-the-use-of-water-('!AA18 -> 1
A19: ='Estimates-on-the-use-of-water-('!Y53 -> 25 | B19: ='Estimates-on-the-use-of-water-('!Z31 -> 6 | C19: ='Estimates-on-the-use-of-water-('!AA19 -> 1
A20: ='Estimates-on-the-use-of-water-('!Y59 -> 25 | B20: ='Estimates-on-the-use-of-water-('!Z46 -> 6 | C20: ='Estimates-on-the-use-of-water-('!AA20 -> 1
A21: ='Estimates-on-the-use-of-water-('!Y145 -> 25 | B21: ='Estimates-on-the-use-of-water-('!Z41 -> 7 | C21: ='Estimates-on-the-use-of-water-('!AA21 -> 1
A22: ='Estimates-on-the-use-of-water-('!Y184 -> 25 | B22: ='Estimates-on-the-use-of-water-('!Z76 -> 7 | C22: ='Estimates-on-the-use-of-water-('!AA22 -> 1
A23: ='Estimates-on-the-use-of-water-('!Y40 -> 26 | B23: ='Estimates-on-the-use-of-water-('!Z116 -> 8 | C23: ='Estimates-on-the-use-of-water-('!AA23 -> 1
A24: ='Estimates-on-the-use-of-water-('!Y55 -> 27 | B24: ='Estimates-on-the-use-of-water-('!Z147 -> 8 | C24: ='Estimates-on-the-use-of-water-('!AA24 -> 1
A25: ='Estimates-on-the-use-of-water-('!Y178 -> 27 | B25: ='Estimates-on-the-use-of-water-('!Z183 -> 8 | C25: ='Estimates-on-the-use-of-water-('!AA25 -> 1
A26: ='Estimates-on-the-use-of-water-('!Y121 -> 28 | B26: ='Estimates-on-the-use-of-water-('!Z23 -> 9 | C26: ='Estimates-on-the-use-of-water-('!AA26 -> 1
A27: ='Estimates-on-the-use-of-water-('!Y188 -> 28 | B27: ='Estimates-on-the-use-of-water-('!Z50 -> 9 | C27: ='Estimates-on-the-use-of-water-('!AA27 -> 1
A28: ='Estimates-on-the-use-of-water-('!Y70 -> 30 | B28: ='Estimates-on-the-use-of-water-('!Z128 -> 9 | C28: ='Estimates-on-the-use-of-water-('!AA28 -> 1
A29: ='Estimates-on-the-use-of-water-('!Y157 -> 31 | B29: ='Estimates-on-the-use-of-water-('!Z204 -> 9 | C29: ='Estimates-on-the-use-of-water-('!AA29 -> 1
A30: ='Estimates-on-the-use-of-water-('!Y38 -> 32 | B30: ='Estimates-on-the-use-of-water-('!Z71 -> 10 | C30: ='Estimates-on-the-use-of-water-('!AA30 -> 1
A31: ='Estimates-on-the-use-of-water-('!Y62 -> 32 | B31: ='Estimates-on-the-use-of-water-('!Z6 -> 11 | C31: ='Estimates-on-the-use-of-water-('!AA31 -> 1
A32: ='Estimates-on-the-use-of-water-('!Y189 -> 32 | B32: ='Estimates-on-the-use-of-water-('!Z42 -> 11 | C32: ='Estimates-on-the-use-of-water-('!AA32 -> 1
A33: ='Estimates-on-the-use-of-water-('!Y142 -> 33 | B33: ='Estimates-on-the-use-of-water-('!Z65 -> 11 | C33: ='Estimates-on-the-use-of-water-('!AA33 -> 1
A34: ='Estimates-on-the-use-of-water-('!Y213 -> 35 | B34: ='Estimates-on-the-use-of-water-('!Z101 -> 12 | C34: ='Estimates-on-the-use-of-water-('!AA34 -> 1
A35: ='Estimates-on-the-use-of-water-('!Y181 -> 36 | B35: ='Estimates-on-the-use-of-water-('!Z107 -> 12 | C35: ='Estimates-on-the-use-of-water-('!AA35 -> 1
A36: ='Estimates-on-the-use-of-water-('!Y191 -> 36 | B36: ='Estimates-on-the-use-of-water-('!Z165 -> 12 | C36: ='Estimates-on-the-use-of-water-('!AA36 -> 1
A37: ='Estimates-on-the-use-of-water-('!Y105 -> 37 | B37: ='Estimates-on-the-use-of-water-('!Z21 -> 13 | C37: ='Estimates-on-the-use-of-water-('!AA37 -> 1
A38: ='Estimates-on-the-use-of-water-('!Y111 -> 37 | B38: ='Estimates-on-the-use-of-water-('!Z22 -> 13 | C38: ='Estimates-on-the-use-of-water-('!AA38 -> 1
A39: ='Estimates-on-the-use-of-water-('!Y141 -> 37 | B39: ='Estimates-on-the-use-of-water-('!Z26 -> 13 | C39: ='Estimates-on-the-use-of-water-('!AA39 -> 1
A40: ='Estimates-on-the-use-of-water-('!Y167 -> 38 | B40: ='Estimates-on-the-use-of-water-('!Z123 -> 13 | C40: ='Estimates-on-the-use-of-water-('!AA40 -> 1
...

Sheet Global 2020 Report.
A1: pop_n | B1: pop_world | C1: pop_u_val
A2: =SUM('Estimates-on-the-use-of-water-('!S:S) -> 7786713708 | B2: =7.821*1000000000 -> 7821000000 | C2: =SUM('Estimates-on-the-use-of-water-('!T:T) -> 4375331317
A11: Metric | B11: Value
A12: Dataset Population | B12: 7786713708
A13: World Population | B13: 7821000000
A14: Population % Difference | B14: =ABS(B12-B13) -> 34286292
A15: Percentage Difference | B15: =(ABS(B12-B13)/((B12+B13)/2))*100 -> 0.4393506
A16: Coverage Percentage | B16: =ABS(B12/B13)*100 -> 99.561612
A23: FEATURES | B23: MAX | C23: MIN | D23: mean | E23: median | F23: mode | G23: QRTL 1 | H23: QRTL 3 | I23: IQR | J23: STDEV
A24: wat_bas_n (Basic water) | B24: =MAX('Estimates-on-the-use-of-water-('!AD:AD) -> 100 | C24: =MIN('Estimates-on-the-use-of-water-('!AD:AD) -> 37 | D24: =AVERAGE('Estimates-on-the-use-of-water-('!AD:AD) -> 89.867299 | E24: =MEDIAN('Estimates-on-the-use-of-water-('!AD:AD) -> 97 | F24: =MODE('Estimates-on-the-use-of-water-('!AD:AD) -> 100 | G24: =_xlfn.QUARTILE.INC('Estimates-on-the-use-of-water-('!AD:AD,1) -> 85.5 | H24: =_xlfn.QUARTILE.INC('Estimates-on-the-use-of-water-('!AD:AD,3) -> 100 | I24: =H24-G24 -> 14.5 | J24: =_xlfn.STDEV.S('Estimates-on-the-use-of-water-('!AD:AD) -> 15.114529
A25: wat_lim_n (Limited water) | B25: =MAX('Estimates-on-the-use-of-water-('!G2:G214) -> 37.426963 | C25: =MIN('Estimates-on-the-use-of-water-('!G:G) -> 0 | D25: =AVERAGE('Estimates-on-the-use-of-water-('!G:G) -> 3.8652653 | E25: =MEDIAN('Estimates-on-the-use-of-water-('!G:G) -> 0.47078292 | F25: =MODE('Estimates-on-the-use-of-water-('!G:G) -> 0 | G25: =_xlfn.QUARTILE.INC('Estimates-on-the-use-of-water-('!G:G,1) -> 0 | H25: =_xlfn.QUARTILE.INC('Estimates-on-the-use-of-water-('!G:G,3) -> 4.8512192 | I25: =H25-G25 -> 4.8512192 | J25: =_xlfn.STDEV.S('Estimates-on-the-use-of-water-('!G:G) -> 6.9608466
A26: wat_unimp_n (Unimproved water) | B26: =MAX('Estimates-on-the-use-of-water-('!H2:H214) -> 33.539114 | C26: =MIN('Estimates-on-the-use-of-water-('!H:H) -> 0 | D26: =AVERAGE('Estimates-on-the-use-of-water-('!H:H) -> 4.4180107 | E26: =MEDIAN('Estimates-on-the-use-of-water-('!H:H) -> 0.85364747 | F26: =MODE('Estimates-on-the-use-of-water-('!H:H) -> 0 | G26: =_xlfn.QUARTILE.INC('Estimates-on-the-use-of-water-('!H:H,1) -> 0.033906223 | H26: =_xlfn.QUARTILE.INC('Estimates-on-the-use-of-water-('!H:H,3) -> 5.2793099 | I26: =H26-G26 -> 5.2454037 | J26: =_xlfn.STDEV.S('Estimates-on-the-use-of-water-('!H:H) -> 7.174477
A27: wat_sur_n (Surface water) | B27: =MAX('Estimates-on-the-use-of-water-('!I2:I214) -> 30.369793 | C27: =MIN('Estimates-on-the-use-of-water-('!I:I) -> 0 | D27: =AVERAGE('Estimates-on-the-use-of-water-('!I:I) -> 1.9154886 | E27: =MEDIAN('Estimates-on-the-use-of-water-('!I:I) -> 0 | F27: =MODE('Estimates-on-the-use-of-water-('!I:I) -> 0 | G27: =_xlfn.QUARTILE.INC('Estimates-on-the-use-of-water-('!I:I,1) -> 0 | H27: =_xlfn.QUARTILE.INC('Estimates-on-the-use-of-water-('!I:I,3) -> 1.878302 | I27: =H27-G27 -> 1.878302 | J27: =_xlfn.STDEV.S('Estimates-on-the-use-of-water-('!I:I) -> 3.923974
A31: Feature | B31: Low (Min) | C31: Open (Q1) | D31: Close (Q3) | E31: High (Max)
A32: wat_bas_n | B32: =C24 -> 37 | C32: =G24 -> 85.5 | D32: =H24 -> 100 | E32: =B24 -> 100
A33: wat_lim_n | B33: =C25 -> 0 | C33: =G25 -> 0 | D33: =H25 -> 4.8512192 | E33: =B25 -> 37.426963
A34: wat_unimp_n | B34: =C26 -> 0 | C34: =G26 -> 0.033906223 | D34: =H26 -> 5.2793099 | E34: =B26 -> 33.539114
A35: wat_sur_n | B35: =C27 -> 0 | C35: =G27 -> 0 | D35: =H27 -> 1.878302 | E35: =B27 -> 30.369793
A47: FEATURES | B47: MAX | C47: MIN | D47: mean | E47: median | F47: mode | G47: QRTL 1 | H47: QRTL 3 | I47: IQR | J47: STDEV
A48: wat_bas_u (Basic water) | B48: =MAX('Estimates-on-the-use-of-water-('!N:N) -> 100 | C48: =MIN('Estimates-on-the-use-of-water-('!N:N) -> 49.661665 | D48: =AVERAGE('Estimates-on-the-use-of-water-('!N:N) -> 94.68984 | E48: =MEDIAN('Estimates-on-the-use-of-water-('!N:N) -> 98.106628 | F48: =MODE('Estimates-on-the-use-of-water-('!N:N) -> 100 | G48: =_xlfn.QUARTILE.INC('Estimates-on-the-use-of-water-('!N:N,1) -> 92.562878 | H48: =_xlfn.QUARTILE.INC('Estimates-on-the-use-of-water-('!N:N,3) -> 99.949418 | I48: =H48-G48 -> 7.3865405 | J48: =_xlfn.STDEV.S('Estimates-on-the-use-of-water-('!N:N) -> 8.0388616
A49: wat_lim_u (Limited water) | B49: =MAX('Estimates-on-the-use-of-water-('!O:O) -> 34.27978 | C49: =MIN('Estimates-on-the-use-of-water-('!O:O) -> 0 | D49: =AVERAGE('Estimates-on-the-use-of-water-('!O:O) -> 3.2818387 | E49: =MEDIAN('Estimates-on-the-use-of-water-('!O:O) -> 0.5 | F49: =MODE('Estimates-on-the-use-of-water-('!O:O) -> 0 | G49: =_xlfn.QUARTILE.INC('Estimates-on-the-use-of-water-('!O:O,1) -> 0 | H49: =_xlfn.QUARTILE.INC('Estimates-on-the-use-of-water-('!O:O,3) -> 3.9663472 | I49: =H49-G49 -> 3.9663472 | J49: =_xlfn.STDEV.S('Estimates-on-the-use-of-water-('!O:O) -> 5.635067
A50: wat_unimp_u (Unimproved water) | B50: =MAX('Estimates-on-the-use-of-water-('!P:P) -> 19.835807 | C50: =MIN('Estimates-on-the-use-of-water-('!P:P) -> 0 | D50: =AVERAGE('Estimates-on-the-use-of-water-('!P:P) -> 1.7187852 | E50: =MEDIAN('Estimates-on-the-use-of-water-('!P:P) -> 0.349874 | F50: =MODE('Estimates-on-the-use-of-water-('!P:P) -> 0 | G50: =_xlfn.QUARTILE.INC('Estimates-on-the-use-of-water-('!P:P,1) -> 0 | H50: =_xlfn.QUARTILE.INC('Estimates-on-the-use-of-water-('!P:P,3) -> 2.0590013 | I50: =H50-G50 -> 2.0590013 | J50: =_xlfn.STDEV.S('Estimates-on-the-use-of-water-('!P:P) -> 3.2345703
A51: wat_sur_u (Surface water) | B51: =MAX('Estimates-on-the-use-of-water-('!Q:Q) -> 6.3621605 | C51: =MIN('Estimates-on-the-use-of-water-('!Q:Q) -> 0 | D51: =AVERAGE('Estimates-on-the-use-of-water-('!Q:Q) -> 0.31311484 | E51: =MEDIAN('Estimates-on-the-use-of-water-('!Q:Q) -> 0 | F51: =MODE('Estimates-on-the-use-of-water-('!Q:Q) -> 0 | G51: =_xlfn.QUARTILE.INC('Estimates-on-the-use-of-water-('!Q:Q,1) -> 0 | H51: =_xlfn.QUARTILE.INC('Estimates-on-the-use-of-water-('!Q:Q,3) -> 0.15970568 | I51: =H51-G51 -> 0.15970568 | J51: =_xlfn.STDEV.S('Estimates-on-the-use-of-water-('!Q:Q) -> 0.86963164
A54: Feature | B54: Low (Min) | C54: Open (Q1) | D54: Close (Q3) | E54: High (Max)
A55: =A48 -> wat_bas_u (Basic water) | B55: =C48 -> 49.661665 | C55: =G48 -> 92.562878 | D55: =H48 -> 99.949418 | E55: =B48 -> 100
A56: =A49 -> wat_lim_u (Limited water) | B56: =C49 -> 0 | C56: =G49 -> 0 | D56: =H49 -> 3.9663472 | E56: =B49 -> 34.27978
A57: =A50 -> wat_unimp_u (Unimproved water) | B57: =C50 -> 0 | C57: =G50 -> 0 | D57: =H50 -> 2.0590013 | E57: =B50 -> 19.835807
A58: =A51 -> wat_sur_u (Surface water) | B58: =C51 -> 0 | C58: =G51 -> 0 | D58: =H51 -> 0.15970568 | E58: =B51 -> 6.3621605
A72: FEATURES | B72: MAX | C72: MIN | D72: mean | E72: median | F72: mode | G72: QRTL 1 | H72: QRTL 3 | I72: IQR | J72: STDEV
A73: wat_bas_r (Basic water) | B73: =MAX('Estimates-on-the-use-of-water-('!J:J) -> 100 | C73: =MIN('Estimates-on-the-use-of-water-('!J:J) -> 21.982792 | D73: =AVERAGE('Estimates-on-the-use-of-water-('!J:J) -> 81.335918 | E73: =MEDIAN('Estimates-on-the-use-of-water-('!J:J) -> 90.731617 | F73: =MODE('Estimates-on-the-use-of-water-('!J:J) -> 100 | G73: =_xlfn.QUARTILE.INC('Estimates-on-the-use-of-water-('!J:J,1) -> 64.825421 | H73: =_xlfn.QUARTILE.INC('Estimates-on-the-use-of-water-('!J:J,3) -> 99.119242 | I73: =H73-G73 -> 34.293821 | J73: =_xlfn.STDEV.S('Estimates-on-the-use-of-water-('!J:J) -> 21.506637
A74: wat_lim_r (Limited water) | B74: =MAX('Estimates-on-the-use-of-water-('!K:K) -> 42.164381 | C74: =MIN('Estimates-on-the-use-of-water-('!K:K) -> 0 | D74: =AVERAGE('Estimates-on-the-use-of-water-('!K:K) -> 5.8365625 | E74: =MEDIAN('Estimates-on-the-use-of-water-('!K:K) -> 1.8123308 | F74: =MODE('Estimates-on-the-use-of-water-('!K:K) -> 0 | G74: =_xlfn.QUARTILE.INC('Estimates-on-the-use-of-water-('!K:K,1) -> 0 | H74: =_xlfn.QUARTILE.INC('Estimates-on-the-use-of-water-('!K:K,3) -> 8.5531751 | I74: =H74-G74 -> 8.5531751 | J74: =_xlfn.STDEV.S('Estimates-on-the-use-of-water-('!K:K) -> 8.7047658
A75: wat_unimp_r (Unimproved water) | B75: =MAX('Estimates-on-the-use-of-water-('!L:L) -> 51.215982 | C75: =MIN('Estimates-on-the-use-of-water-('!L:L) -> 0 | D75: =AVERAGE('Estimates-on-the-use-of-water-('!L:L) -> 8.7322615 | E75: =MEDIAN('Estimates-on-the-use-of-water-('!L:L) -> 3.2297497 | F75: =MODE('Estimates-on-the-use-of-water-('!L:L) -> 0 | G75: =_xlfn.QUARTILE.INC('Estimates-on-the-use-of-water-('!L:L,1) -> 0.15841092 | H75: =_xlfn.QUARTILE.INC('Estimates-on-the-use-of-water-('!L:L,3) -> 13.266339 | I75: =H75-G75 -> 13.107928 | J75: =_xlfn.STDEV.S('Estimates-on-the-use-of-water-('!L:L) -> 11.828494
A76: wat_sur_r (Surface water) | B76: =MAX('Estimates-on-the-use-of-water-('!M:M) -> 40.518132 | C76: =MIN('Estimates-on-the-use-of-water-('!M:M) -> 0 | D76: =AVERAGE('Estimates-on-the-use-of-water-('!M:M) -> 4.2240396 | E76: =MEDIAN('Estimates-on-the-use-of-water-('!M:M) -> 0.21968974 | F76: =MODE('Estimates-on-the-use-of-water-('!M:M) -> 0 | G76: =_xlfn.QUARTILE.INC('Estimates-on-the-use-of-water-('!M:M,1) -> 0 | H76: =_xlfn.QUARTILE.INC('Estimates-on-the-use-of-water-('!M:M,3) -> 6.1574715 | I76: =H76-G76 -> 6.1574715 | J76: =_xlfn.STDEV.S('Estimates-on-the-use-of-water-('!M:M) -> 6.8479514
A80: Feature | B80: Low (Min) | C80: Open (Q1) | D80: Close (Q3) | E80: High (Max)
A81: =A73 -> wat_bas_r (Basic water) | B81: =C73 -> 21.982792 | C81: =G73 -> 64.825421 | D81: =H73 -> 99.119242 | E81: =B73 -> 100
A82: =A74 -> wat_lim_r (Limited water) | B82: =C74 -> 0 | C82: =G74 -> 0 | D82: =H74 -> 8.5531751 | E82: =B74 -> 42.164381
A83: =A75 -> wat_unimp_r (Unimproved water) | B83: =C75 -> 0 | C83: =G75 -> 0.15841092 | D83: =H75 -> 13.266339 | E83: =B75 -> 51.215982
A84: =A76 -> wat_sur_r (Surface water) | B84: =C76 -> 0 | C84: =G76 -> 0 | D84: =H76 -> 6.1574715 | E84: =B76 -> 40.518132
A99: Feature | B99: Low (Min) | C99: Open (Q1) | D99: Close (Q3) | E99: High (Max)
A100: wat_bas_n | B100: 37 | C100: 85.5 | D100: 100 | E100: 100
...

Sheet access distribution dashboard
A2: Feature | B2: Low (Min) | C2: Open (Q1) | D2: Close (Q3) | E2: High (Max)
A3: wat_bas_n | B3: 37 | C3: 85.5 | D3: 100 | E3: 100
A4: wat_lim_n | B4: 0 | C4: 0 | D4: 4.8512192 | E4: 37.426963
A5: wat_unimp_n | B5: 0 | C5: 0.033906223 | D5: 5.2793099 | E5: 33.539114
A6: wat_sur_n | B6: 0 | C6: 0 | D6: 1.878302 | E6: 30.369793
A7: wat_bas_u (Basic water) | B7: 49.661665 | C7: 92.562878 | D7: 99.949418 | E7: 100
A8: wat_lim_u (Limited water) | B8: 0 | C8: 0 | D8: 3.9663472 | E8: 34.27978
A9: wat_unimp_u (Unimproved water) | B9: 0 | C9: 0 | D9: 2.0590013 | E9: 19.835807
A10: wat_sur_u (Surface water) | B10: 0 | C10: 0 | D10: 0.15970568 | E10: 6.3621605
A11: wat_bas_r (Basic water) | B11: 21.982792 | C11: 64.825421 | D11: 99.119242 | E11: 100
A12: wat_lim_r (Limited water) | B12: 0 | C12: 0 | D12: 8.5531751 | E12: 42.164381
A13: wat_unimp_r (Unimproved water) | B13: 0 | C13: 0.15841092 | D13: 13.266339 | E13: 51.215982
A14: wat_sur_r (Surface water) | B14: 0 | C14: 0 | D14: 6.1574715 | E14: 40.518132

Sheet ORDERED AND AGGREGATED POPvsACC
R5: COMMENT
R6: Analysis | S6: Independent variable | T6: Main observation
R7: National | S7: Population size | T7: No clear, consistent relationship
R8: Urban | S8: Urban population share | T8: Basic access remains dominant across most groups
R9: Rural | S9: Rural population share | T9: Higher rural shares appear to coincide with more lower-level access

Sheet Sheet2

Sheet Sheet6
